<?xml version="1.0"?>
<robot name="Phoenix">
	<link name="base_link">
		<visual>
			<geometry>
				<cylinder length="1.5" radius="0.4"/>
			</geometry>
			<material name="red">
				<color rgba=".64 0 .1 1" />
			</material>
			<origin rpy="0 1.57 0 " xyz="0 0 0 " />
		</visual>
	</link>
	<link name="base_yaw" />
	<link name="base_pitch" />
	<link name="base_roll" />
	<link name="base_x" />
	<link name="base_y" />
	<link name="base_z" />
 

	<joint name="x" type="continuous">
		<parent link="base_link" />
		<child link="base_x" />
		<origin xyz="0 0 0" rpy="0 0 0" />
		<axis xyz="1 0 0" />
		<limit velocity="0.3" effort="30" />
		<safety_controller k_velocity="10" soft_lower_limit="0.1" soft_upper_limit="0.9"/>
	</joint>
	 
	<joint name="y" type="continuous">
		<parent link="base_x" />
		<child link="base_y" />
		<origin xyz="0 0 0" rpy="0 0 0" />
		<axis xyz="0 1 0" />
		<limit velocity="0.3" effort="30" />
		<safety_controller k_position="100" k_velocity="10" soft_lower_limit="0.1" soft_upper_limit="0.9"/>		
	</joint>
 
	<joint name="z" type="continuous">
		<parent link="base_y" />
		<child link="base_z" />
		<origin xyz="0 0 0" rpy="0 0 0" />	
		<axis xyz="0 0 1" />
		<limit velocity="0.3" effort="30" />
		<safety_controller k_position="100" k_velocity="10" soft_lower_limit="0.1" soft_upper_limit="0.9"/>		
	</joint>
 
	<joint name="yaw" type="continuous">
		<parent link="base_z" />
		<child link="base_yaw" />
		<origin xyz="0 0 0" rpy="0 0 0" />
		<axis xyz="0 0 1" />
		<limit velocity="0.147" effort="50" />
		<safety_controller k_velocity="10" soft_lower_limit="0.1" soft_upper_limit="0.9"/>		
	</joint>
 
	<joint name="pitch" type="revolute">
		<parent link="base_yaw" />
		<child link="base_pitch" />
		<origin xyz="0 0 0" rpy="0 0 0" />
		<axis xyz="0 1 0" />
		<limit lower="-1.39" upper="1.39" velocity="0.147" effort="50" />
		<safety_controller k_position="100" k_velocity="10" soft_lower_limit="0.1" soft_upper_limit="0.9"/>
	</joint>
 
	<joint name="roll" type="continuous">
		<parent link="base_pitch" />
		<child link="base_roll" />
		<origin xyz="0 0 0" rpy="0 0 0" />	
		<axis xyz="1 0 0" />
		<limit lower="-1.39" upper="1.39" velocity="0.147" effort="50" />
		<safety_controller k_position="100" k_velocity="10" soft_lower_limit="0.1" soft_upper_limit="0.9"/>		
	</joint>

	<link name="surge_thruster">
		<limit effort="35" />		
	</link>
	<link name="front_yaw_thruster">
		<limit effort="28.4" />		
	</link>
	<link name="stern_yaw_thruster">
		<limit effort="28.4" />		
	</link>
	<link name="front_pitch_thruster">
		<limit effort="28.4" />		
	</link>
	<link name="stern_pitch_thruster">
		<limit effort="28.4" />		
	</link>


	<joint name="surge_thruster_joint" type="continuous">
		<parent link="base_link" />
		<child link="surge_thruster" />
		<origin xyz="-1.8 0 0" rpy="0 0 0" />
		<axis xyz="1 0 0" />		
	</joint>

	<joint name="front_yaw_thruster_joint" type="continuous">
		<parent link="base_link" />
		<child link="front_yaw_thruster" />
		<origin xyz="1.6 0 0" rpy="0 0 1.571" />
		<axis xyz="1 0 0" />		
	</joint>

	<joint name="stern_yaw_thruster_joint" type="continuous">
		<parent link="base_link" />
		<child link="stern_yaw_thruster" />
		<origin xyz="-1.6 0 0" rpy="0 0 1.571" />
		<axis xyz="1 0 0" />		
	</joint>

	<joint name="front_pitch_thruster_joint" type="continuous">
		<parent link="base_link" />
		<child link="front_pitch_thruster" />
		<origin xyz="1.5 0 0" rpy="0 1.571 0" />
		<axis xyz="1 0 0" />		
	</joint>

	<joint name="stern_pitch_thruster_joint" type="continuous">
		<parent link="base_link" />
		<child link="stern_pitch_thruster" />
		<origin xyz="-1.5 0 0" rpy="0 1.57 0" />
		<axis xyz="1 0 0" />
	</joint>
	
	<link name="stump">
		<visual>
			<geometry>
				<box size="0.6 0.05 0.05" />
			</geometry>
			<material name="grey" >
				<color rgba=".64 .64 .64 1" />
			</material>
			<origin xyz="0.3 0 0" rpy="0 0 0" />
		</visual>
	</link>
	<link name="gripper">
		<visual>
			<geometry>
				<cylinder length="0.15" radius="0.05"/>
			</geometry>
			<material name="grey" />
			<origin xyz="0.075 0 0" rpy="0 1.57 0" />
		</visual>
	</link>
	<link name="xsens">
		<visual>
			<geometry>
				<box size="0.05 0.05 0.05" />
			</geometry>
			<material name="blue" >
				<color rgba="0 0 .8 1"/>
			</material>
		</visual>
	</link>		 
	<link name="IMU_Vectornav">
		<visual>
			<geometry>
				<box size="0.05 0.05 0.05" />
			</geometry>
			<material name="blue" />
		</visual>
	</link> 


	<joint name="stiff_shoulder" type="fixed">
		<parent link="base_link" />
		<child link="stump" />
		<origin xyz="0 0 0" rpy="0 0 -1.57" />		
		<axis xyz="0 0 0" />
	</joint>
 
	<joint name="wrist_rotate" type="continuous">
		<parent link="stump" />
		<child link="gripper" />
		<origin xyz="0.6 0 0" rpy="0 0 0" />		
		<axis xyz="1 0 0" />		
	</joint>
 
	<joint name="Joint_for_xsens" type="fixed">
		<parent link="base_link" />
		<child link="xsens" />
		<origin xyz="0 0 0" rpy="0 0 0" />
		<axis xyz="0 0 0 " />
	</joint>
 
	<joint name="Joint_for_Vectornav" type="fixed">
		<parent link="base_link" />
		<child link="IMU_Vectornav" />
		<origin xyz="0.3 0 0.4" rpy="0 0 0" />
		<axis xyz="0 0 0 " />
	</joint>
		
<!--	<link name="SVS">
		<visual>
			<geometry>
				<box size="0.05 0.05 0.05" />
			</geometry>
			<material name="blue" />
		</visual>
	</link>
	<link name="SONAR_UWESUB">
		<visual>
			<geometry>
				<box size="0.05 0.05 0.05" />
			</geometry>
			<material name="blue" />
		</visual>
	</link> 
	<link name="SONAR_BMT">
		<visual>
			<geometry>
				<box size="0.05 0.05 0.05" />
			</geometry>
			<material name="blue" />
		</visual>
	</link>
	<link name="SVS_mount">
	</link>		
	<link name="SONAR_UWESUB_mount">
	</link> 
	<link name="SONAR_BMT_mount">
	</link> -->


 	
 	<!-- Absolute Data from the two SONARs and the SVS --> 
	<!-- SONAR and SVS will need a dynamic transform 'odom->xxx_base' published somewhere -->

<!--	<joint name="Joint_for_SVS_mounting_position" type="fixed">
		<parent link="SVS" />
		<child link="SVS_mount" />
		<origin xyz="0.0 0 0.0" rpy="0 0 0" />
		<axis xyz="0 0 0 " />
	</joint>

 	<joint name="Joint_SONAR_UWESUB_mounting_position" type="fixed">
		<parent link="SONAR_UWESUB" />
		<child link="SONAR_UWESUB_mount" />
		<origin xyz="0.0 0 0.0" rpy="0 0 0" />
		<axis xyz="0 0 0 " />
	</joint>
 	<joint name="JOINT_SONAR_BMT_mounting_position" type="fixed">
		<parent link="SONAR_BMT" />
		<child link="SONAR_BMT_mount" />
		<origin xyz="0.3 0 0.4" rpy="0 0 0" />
		<axis xyz="0 0 0 " />
	</joint> -->

<!-- I think I have to publish them with the message it self
 	<joint name="Joint_SONAR_UWESUB_beam" type="fixed">
		<parent link="SONAR_UWESUB_base" />
		<child link="SONAR_UWESUB_beam" />
		<origin xyz="0 0 0" rpy="0 0 0" />
		<axis xyz="0 0 0 " />
	</joint>
 	<joint name="JOINT_SONAR_BMT_beam" type="fixed">
		<parent link="SONAR_BMT_base" />
		<child link="SONAR_BMT_beam" />
		<origin xyz="0 0 0" rpy="0 0 0" />
		<axis xyz="0 0 0 " />
	</joint>	
	-->		

</robot>


